<?xml version="1.0"?>
<!--
  Hexagon stacks
 -->
<robot name="component_gripper" xmlns:xacro="http://www.ros.org/wiki/xacro">

  <xacro:property name="M_PI" value="3.1415926535897931" /> 
  
  <!-- Xacro properties -->
  <xacro:property name="gripper_mass" value="0.3" />
  <xacro:property name="finger_mass" value="0.1" />
  <!-- Xacro macros -->
  <xacro:macro name="component_gripper" params="parent">

  <!--links-->
  <link name="gripper_link">
    <inertial>
      <origin xyz="0 0 0" rpy="0 0 0"/>
      <mass value="${gripper_mass}"/>
      <inertia ixx="0.0001" ixy="0" ixz="0" iyy="0.0002" iyz="0" izz="0.0001"/>
    </inertial>
    <visual>
      <origin xyz="0 0 0" rpy="0 0 0"/>
      <geometry>
        <mesh filename="package://iiwa_arm/meshes/gripper/gripper_base.dae" scale="0.5 0.4 0.3"/>
      </geometry>
    </visual>
    <collision>
      <origin xyz="0 0 0" rpy="0 0 0"/>
      <geometry>
        <mesh filename="package://iiwa_arm/meshes/gripper/gripper_base.dae" scale="0.5 0.4 0.3"/>
      </geometry>
    </collision>
  </link>
  <link name="right_gripper_finger_link">
    <inertial>
      <origin xyz="0 0 0" rpy="0 0 0"/>
      <mass value="${finger_mass}"/>
      <inertia ixx="0.002" ixy="0" ixz="0" iyy="0.0002" iyz="0" izz="0.0002"/>
    </inertial>
    <visual>
      <origin xyz="0 0 0" rpy="0 0 0"/>
      <geometry>
        <mesh filename="package://iiwa_arm/meshes/gripper/finger_right.dae" scale="0.5 0.5 0.5"/>
      </geometry>
    </visual>
    <collision>
      <origin xyz="0 0 0" rpy="0 0 0"/>
      <geometry>
        <mesh filename="package://iiwa_arm/meshes/gripper/finger_right_collision.dae" scale="0.5 0.5 0.5"/>
      </geometry>
    </collision>
  </link>
  <link name="left_gripper_finger_link">
    <inertial>
      <origin xyz="0 0 0" rpy="0 0 0"/>
      <mass value="${finger_mass}"/>
      <inertia ixx="0.002" ixy="0" ixz="0" iyy="0.0002" iyz="0" izz="0.0002"/>
    </inertial>
    <visual>
      <origin xyz="0 0 0" rpy="0 0 0"/>
      <geometry>
        <mesh filename="package://iiwa_arm/meshes/gripper/finger_left.dae" scale="0.5 0.5 0.5"/>
      </geometry>
    </visual>
    <collision>
      <origin xyz="0 0 0" rpy="0 0 0"/>
      <geometry>
        <mesh filename="package://iiwa_arm/meshes/gripper/finger_left_collision.dae" scale="0.5 0.5 0.5"/>
      </geometry>
    </collision>
  </link>

  <!--Joints-->
  <joint name="right_gripper_finger_joint" type="prismatic">
    <origin rpy="0 0 0" xyz="${0.15/2} ${-0.0725/2.5} 0" />
    <parent link="gripper_link" />
    <child link="right_gripper_finger_link" />
    <axis xyz="0 1 0" />
    <limit effort="100" lower="-0.01" upper="0.03" velocity="0.5" />
    <dynamics damping="0.7" friction="0.5"/>
  </joint>

  <joint name="left_gripper_finger_joint" type="prismatic">
    <origin rpy="0 0 0" xyz="${0.15/2} ${0.0725/2.5} 0" />
    <parent link="gripper_link" />
    <child link="left_gripper_finger_link" />
    <axis xyz="0 -1 0" />
    <limit effort="100" lower="-0.01" upper="0.03" velocity="0.5" />
    <dynamics damping="0.7" friction="0.5"/>
  </joint>

  <joint name="gripper_joint" type="fixed">
    <parent link="${parent}"/>
    <child link="gripper_link"/>
    <origin xyz="0 0 ${0.045+0.035}" rpy="0 -${M_PI/2} 0"/>
    <axis xyz="0 1 0" />
  </joint>

<!--transmissions-->
  <transmission name="tran8">
    <type>transmission_interface/SimpleTransmission</type>
    <joint name="left_gripper_finger_joint">
      <hardwareInterface>hardware_interface/EffortJointInterface</hardwareInterface>
    </joint>
    <actuator name="motor8">
      <hardwareInterface>hardware_interface/EffortJointInterface</hardwareInterface>
      <mechanicalReduction>1</mechanicalReduction>
    </actuator>
  </transmission>

  <transmission name="tran9">
    <type>transmission_interface/SimpleTransmission</type>
    <joint name="right_gripper_finger_joint">
      <hardwareInterface>hardware_interface/EffortJointInterface</hardwareInterface>
    </joint>
    <actuator name="motor9">
      <hardwareInterface>hardware_interface/EffortJointInterface</hardwareInterface>
      <mechanicalReduction>1</mechanicalReduction>
    </actuator>
  </transmission>

  <!-- grasp plugin -->
  <gazebo>
    <plugin name="gazebo_grasp_fix" filename="libgazebo_grasp_fix.so">
      <arm>
        <arm_name>iiwa_arm</arm_name>
        <palm_link>link_7</palm_link>
        <gripper_link>right_gripper_finger_link</gripper_link>
        <gripper_link>left_gripper_finger_link</gripper_link>
      </arm>
      <forces_angle_tolerance>100</forces_angle_tolerance>
      <update_rate>30</update_rate>
      <grip_count_threshold>4</grip_count_threshold>
      <max_grip_count>8</max_grip_count>
      <release_tolerance>0.0005</release_tolerance>
      <disable_collisions_on_attach>false</disable_collisions_on_attach>
      <contact_topic>__default_topic__</contact_topic>
    </plugin>
  </gazebo>

  </xacro:macro>
</robot>
